Workbook

Sheet Laptop only
A1: No. | B1: Full Name | C1: Initials | D1: Division | E1: Position | F1: Model | G1: Brand | H1: Year Acquired/Transferred | I1: Years in service | J1: Serial Number | K1: Method of Procurement | L1: Current Custodian | M1: Remarks
A2: 1 | B2: Editha T. Ramos | C2: ETR | D2: EPRED | E2: Chief | F2: Predator Helios 300 | G2: =VLOOKUP(F2,Data!$B$122:$C$135,2,FALSE) -> Acer | H2: =VLOOKUP(F2,Data!$B$122:$D$135,3,FALSE) -> 2021 | I2: =YEAR(TODAY()) - H2 -> 5 | J2: NHQAUSP00111116A333400 | K2: Through LFP | L2: Editha T. Ramos
D3: EPRED | F3: Macbook Pro 13 Inch M2 | G3: =VLOOKUP(F3,Data!$B$122:$C$135,2,FALSE) -> Apple | H3: =VLOOKUP(F3,Data!$B$122:$D$135,3,FALSE) -> 2023 | I3: =YEAR(TODAY()) - H3 -> 3 | K3: Through LFP | L3: Editha T. Ramos
A4: 2 | B4: Roselle L. Ibuna | C4: RLI | D4: EPRED | E4: OIC-Supervising Science Research Specialist | F4: Macbook Pro 13 Inch M2 | G4: =VLOOKUP(F4,Data!$B$122:$C$135,2,FALSE) -> Apple | H4: =VLOOKUP(F4,Data!$B$122:$D$135,3,FALSE) -> 2023 | I4: =YEAR(TODAY()) - H4 -> 3 | J4: CJ7KXX9JKD | K4: Through LFP | L4: Roselle L. Ibuna
D5: EPRED | F5: TUF | G5: =VLOOKUP(F5,Data!$B$122:$C$135,2,FALSE) -> Asus | H5: =VLOOKUP(F5,Data!$B$122:$D$135,3,FALSE) -> 2020 | I5: =YEAR(TODAY()) - H5 -> 6 | J5: L8NRCX029705339 | K5: Through LFP | L5: Transfer to EVIMD (c/o Jenny Ramos)
D6: EPRED | F6: Predator Helios 300 | G6: =VLOOKUP(F6,Data!$B$122:$C$135,2,FALSE) -> Acer | H6: =VLOOKUP(F6,Data!$B$122:$D$135,3,FALSE) -> 2021 | I6: =YEAR(TODAY()) - H6 -> 5 | J6: L8NRCX029705339 | K6: Through LFP | L6: Suzanne M. Pantaleon
A7: 3 | B7: Joan C. Escalona | C7: JCE | D7: EPRED | E7: Supervising Science Research Specialist | F7: Predator Helios 16 | G7: =VLOOKUP(F7,Data!$B$122:$C$135,2,FALSE) -> Acer | H7: =VLOOKUP(F7,Data!$B$122:$D$135,3,FALSE) -> 2024 | I7: =YEAR(TODAY()) - H7 -> 2 | J7: NHQNXSP00141300BAC7600 | K7: Through LFP | L7: Mary Ann M. Fernando
D8: EPRED | F8: Macbook Pro 13 Inch M2 | G8: =VLOOKUP(F8,Data!$B$122:$C$135,2,FALSE) -> Apple | H8: =VLOOKUP(F8,Data!$B$122:$D$135,3,FALSE) -> 2023 | I8: =YEAR(TODAY()) - H8 -> 3 | J8: MJL6KWYPVW | K8: Through LFP | L8: Joan C. Escalona
A9: 4 | B9: Steven Ivan G. Caiña | C9: SIGC | D9: EPRED | E9: OIC-Senior Science Research Specialist | F9: Macbook Pro 14 Inch M2 | G9: =VLOOKUP(F9,Data!$B$122:$C$135,2,FALSE) -> Apple | H9: =VLOOKUP(F9,Data!$B$122:$D$135,3,FALSE) -> 2023 | I9: =YEAR(TODAY()) - H9 -> 3 | J9: D6KCXF4R9D | K9: Through LFP | L9: Steven Ivan G. Caiña
D10: EPRED | F10: Predator Helios 300 | G10: =VLOOKUP(F10,Data!$B$122:$C$135,2,FALSE) -> Acer | H10: =VLOOKUP(F10,Data!$B$122:$D$135,3,FALSE) -> 2021 | I10: =YEAR(TODAY()) - H10 -> 5 | J10: NHQAUSPOO1111177763400 | K10: Through LFP | L10: Sheila C. Gadil
D11: EPRED | F11: Predator Helios 300 | G11: =VLOOKUP(F11,Data!$B$122:$C$135,2,FALSE) -> Acer | H11: =VLOOKUP(F11,Data!$B$122:$D$135,3,FALSE) -> 2021 | I11: =YEAR(TODAY()) - H11 -> 5 | J11: NHQAUSP0011111767D3400 | K11: Through LFP | L11: Carlo S. Arriola
D12: EPRED | F12: Predator Helios 300 | G12: =VLOOKUP(F12,Data!$B$122:$C$135,2,FALSE) -> Acer | H12: =VLOOKUP(F12,Data!$B$122:$D$135,3,FALSE) -> 2021 | I12: =YEAR(TODAY()) - H12 -> 5 | J12: NHQAUSPOO11111720E3400 | K12: Through LFP | L12: Argy E. Gatdula
D13: EPRED | F13: Predator Helios 300 | G13: =VLOOKUP(F13,Data!$B$122:$C$135,2,FALSE) -> Acer | H13: =VLOOKUP(F13,Data!$B$122:$D$135,3,FALSE) -> 2021 | I13: =YEAR(TODAY()) - H13 -> 5 | J13: NHQC1SP002147275433400 | K13: Through LFP | L13: Benlie Mae B. Antonio
D14: EPRED | F14: TUF | G14: =VLOOKUP(F14,Data!$B$122:$C$135,2,FALSE) -> Asus | H14: =VLOOKUP(F14,Data!$B$122:$D$135,3,FALSE) -> 2020 | I14: =YEAR(TODAY()) - H14 -> 6 | J14: L8NRCX029725337 | K14: Through LFP | L14: Ara Jane C. Canaria
A15: 5 | B15: Aaron R. Premacio | C15: ARP | D15: EPRED | E15: Senior Science Research Specialist | F15: Predator Helios 16 | G15: =VLOOKUP(F15,Data!$B$122:$C$135,2,FALSE) -> Acer | H15: =VLOOKUP(F15,Data!$B$122:$D$135,3,FALSE) -> 2024 | I15: =YEAR(TODAY()) - H15 -> 2 | J15: NHQNXSP00141300C387600 | K15: Through LFP | L15: Aaron R. Premacio
D16: EPRED | F16: Predator Helios 300 | G16: =VLOOKUP(F16,Data!$B$122:$C$135,2,FALSE) -> Acer | H16: =VLOOKUP(F16,Data!$B$122:$D$135,3,FALSE) -> 2021 | I16: =YEAR(TODAY()) - H16 -> 5 | K16: Through LFP | L16: Michael Angelo O. Guarin
D17: EPRED | F17: TUF | G17: =VLOOKUP(F17,Data!$B$122:$C$135,2,FALSE) -> Asus | H17: =VLOOKUP(F17,Data!$B$122:$D$135,3,FALSE) -> 2020 | I17: =YEAR(TODAY()) - H17 -> 6 | J17: L8NRCX02972133B | K17: Through LFP | L17: Kristine Joy. B. Villaluz
A18: 6 | B18: Celedonio Tiu Salle | C18: CTS | D18: EPRED | E18: Senior Science Research Specialist | F18: Predator Helios 16 | G18: =VLOOKUP(F18,Data!$B$122:$C$135,2,FALSE) -> Acer | H18: =VLOOKUP(F18,Data!$B$122:$D$135,3,FALSE) -> 2024 | I18: =YEAR(TODAY()) - H18 -> 2 | J18: NHQNXSP00141300C097600 | K18: Through LFP | L18: Celedonio Tiu Salle
A19: 7 | B19: Erwin-Lou D. Peregrino | C19: EDP | D19: EPRED | E19: Science Research Specialist II | F19: Predator Helios 16 | G19: =VLOOKUP(F19,Data!$B$122:$C$135,2,FALSE) -> Acer | H19: =VLOOKUP(F19,Data!$B$122:$D$135,3,FALSE) -> 2024 | I19: =YEAR(TODAY()) - H19 -> 2 | J19: NHQNXSP00141300A5D7600 | K19: Through LFP | L19: Erwin-Lou D. Peregrino
D20: EPRED | F20: Predator Helios 16 | G20: =VLOOKUP(F20,Data!$B$122:$C$135,2,FALSE) -> Acer | H20: =VLOOKUP(F20,Data!$B$122:$D$135,3,FALSE) -> 2024 | I20: =YEAR(TODAY()) - H20 -> 2 | J20: NHQNXSP0014130097B7600 | K20: Through LFP | L20: James C. Francisco
A21: 8 | B21: Catherine C. Cadiz | C21: CCC | D21: EPRED | E21: Science Research Specialist II | F21: Predator Helios 16 | G21: =VLOOKUP(F21,Data!$B$122:$C$135,2,FALSE) -> Acer | H21: =VLOOKUP(F21,Data!$B$122:$D$135,3,FALSE) -> 2024 | I21: =YEAR(TODAY()) - H21 -> 2 | J21: NHQNXSP00141300BDE7600 | K21: Through LFP | L21: Catherine C. Cadiz
D22: EPRED | F22: Macbook Pro 13 Inch M2 | G22: =VLOOKUP(F22,Data!$B$122:$C$135,2,FALSE) -> Apple | H22: =VLOOKUP(F22,Data!$B$122:$D$135,3,FALSE) -> 2023 | I22: =YEAR(TODAY()) - H22 -> 3 | K22: Through LFP | L22: Catherine C. Cadiz | M22: Reserve | N22: Reymund G. Fiecas - Lserv to be deploy
A23: 9 | B23: Chesca Mie A. Gaduyon | C23: CMAG | D23: EPRED | E23: Science Research Specialist II | F23: Macbook Pro 13 Inch M2 | G23: =VLOOKUP(F23,Data!$B$122:$C$135,2,FALSE) -> Apple | H23: =VLOOKUP(F23,Data!$B$122:$D$135,3,FALSE) -> 2023 | I23: =YEAR(TODAY()) - H23 -> 3 | J23: CWDKH2WLT6 | K23: Through LFP | L23: Chesca Mie A. Gaduyon
A24: 10 | B24: Marienelle S. Santos | C24: MSS | D24: EPRED | E24: Science Research Specialist II | F24: Macbook Pro 13 Inch M2 | G24: =VLOOKUP(F24,Data!$B$122:$C$135,2,FALSE) -> Apple | H24: =VLOOKUP(F24,Data!$B$122:$D$135,3,FALSE) -> 2023 | I24: =YEAR(TODAY()) - H24 -> 3 | J24: SHXJLD2TQ1WFV | K24: Through LFP | L24: Marienelle S. Santos
D25: EPRED | F25: Macbook Air 13 inch M1 | G25: =VLOOKUP(F25,Data!$B$122:$C$135,2,FALSE) -> Apple | H25: =VLOOKUP(F25,Data!$B$122:$D$135,3,FALSE) -> 2022 | I25: =YEAR(TODAY()) - H25 -> 4 | K25: Through LFP | L25: Hannah Isabel L. Cumpas
A26: 11 | B26: Daniel Vincent P. De Guzman | C26: DVDG | D26: EPRED | E26: Science Research Specialist II | F26: Predator Helios 16 | G26: =VLOOKUP(F26,Data!$B$122:$C$135,2,FALSE) -> Acer | H26: =VLOOKUP(F26,Data!$B$122:$D$135,3,FALSE) -> 2024 | I26: =YEAR(TODAY()) - H26 -> 2 | J26: NHQNXSP00141300C8C7600 | K26: Through LFP | L26: Daniel Vincent P. De Guzman
A27: 12 | B27: Von Jari A. Anievas | C27: VJA | D27: EPRED | E27: Science Research Specialist I | F27: Predator Helios 16 | G27: =VLOOKUP(F27,Data!$B$122:$C$135,2,FALSE) -> Acer | H27: =VLOOKUP(F27,Data!$B$122:$D$135,3,FALSE) -> 2024 | I27: =YEAR(TODAY()) - H27 -> 2 | L27: Von Jari A. Anievas
A28: 12 | B28: Chester Syrill J. De Castro | C28: CSJDC | D28: EPRED | E28: Science Research Specialist I | F28: Predator Helios 300 | G28: =VLOOKUP(F28,Data!$B$122:$C$135,2,FALSE) -> Acer | H28: =VLOOKUP(F28,Data!$B$122:$D$135,3,FALSE) -> 2021 | I28: =YEAR(TODAY()) - H28 -> 5 | J28: NHQAUSP001111167B03400 | K28: Through LFP | L28: Chester Syrill J. De Castro | M28: Reserve | N28: Lserv to be deploy
F29: Macbook Pro 13 Inch M2 | G29: =VLOOKUP(F29,Data!$B$122:$C$135,2,FALSE) -> Apple | H29: =VLOOKUP(F29,Data!$B$122:$D$135,3,FALSE) -> 2023 | I29: =YEAR(TODAY()) - H29 -> 3 | K29: Through LFP | L29: Chester Syrill J. De Castro
A30: 13 | B30: Marvin B. Bahia | C30: MBB | D30: EPRED | E30: Science Research Specialist I | F30: Predator Helios 300 | G30: =VLOOKUP(F30,Data!$B$122:$C$135,2,FALSE) -> Acer | H30: =VLOOKUP(F30,Data!$B$122:$D$135,3,FALSE) -> 2021 | I30: =YEAR(TODAY()) - H30 -> 5 | J30: NHQAUSP001111172DB3400 | K30: Through LFP | L30: Marvin B. Bahia
A31: 14 | B31: Christine Joy M. Lamzon | C31: CJML | D31: EPRED | E31: Administrative Aide VI | F31: Predator Helios 16 | G31: =VLOOKUP(F31,Data!$B$122:$C$135,2,FALSE) -> Acer | H31: =VLOOKUP(F31,Data!$B$122:$D$135,3,FALSE) -> 2024 | I31: =YEAR(TODAY()) - H31 -> 2 | J31: NHQNXSP001413009A37600 | K31: Through LFP | L31: Christine Joy M. Lamzon
A32: 17 | B32: Daniel Collin G. Jornales | C32: DCGJ | D32: EPMPD | E32: Chief Science Research Specialist | F32: Macbook Pro 14 Inch M2 | G32: =VLOOKUP(F32,Data!$B$122:$C$135,2,FALSE) -> Apple | H32: =VLOOKUP(F32,Data!$B$122:$D$135,3,FALSE) -> 2023 | I32: 1 | J32: CGQJ1YYVKC | K32: Through LFP | L32: Hans Christer A. Arcilla
D33: EPMPD | F33: Predator Helios 16 | G33: =VLOOKUP(F33,Data!$B$122:$C$135,2,FALSE) -> Acer | H33: =VLOOKUP(F33,Data!$B$122:$D$135,3,FALSE) -> 2024 | I33: =YEAR(TODAY()) - H33 -> 2 | J33: NHQNXSP00141300AD77600 | K33: Through LFP | L33: Mark Adrian A. Aclon
A34: 18 | B34: Cynthia P.J. Mañalac | C34: CPJM | D34: EPMPD | E34: Supervising Science Research Specialist | F34: Travelmate | G34: =VLOOKUP(F34,Data!$B$122:$C$135,2,FALSE) -> Acer | H34: =VLOOKUP(F34,Data!$B$122:$D$135,3,FALSE) -> 2022 | I34: 1 | K34: ITMS | L34: Judy Ann P. Santos | M34: For Transfer
D35: EPMPD | F35: Macbook Pro 13 Inch M2 | G35: Apple | H35: 2023 | I35: 3 | K35: Through LFP
A36: 19 | B36: Christian Harris T. Hernaez | C36: CHTH | D36: EPMPD | E36: OIC Supervising Science Research Specialist | F36: Macbook Pro 13 Inch M2 | G36: =VLOOKUP(F36,Data!$B$122:$C$135,2,FALSE) -> Apple | H36: =VLOOKUP(F36,Data!$B$122:$D$135,3,FALSE) -> 2023 | I36: =YEAR(TODAY()) - H36 -> 3 | J36: XHW7KY7CQV | K36: Through LFP | L36: Christian Harris T. Hernaez
D37: EPMPD | F37: Macbook Air 13 inch 2017 | G37: =VLOOKUP(F37,Data!$B$122:$C$135,2,FALSE) -> Apple | H37: =VLOOKUP(F37,Data!$B$122:$D$135,3,FALSE) -> 2017 | I37: =YEAR(TODAY()) - H37 -> 9 | J37: FVFY486Z1WK | K37: Through LFP | L37: Christian Harris T. Hernaez | M37: For RTS
D38: EPMPD | F38: Predator Helios 16 | G38: =VLOOKUP(F38,Data!$B$122:$C$135,2,FALSE) -> Acer | H38: =VLOOKUP(F38,Data!$B$122:$D$135,3,FALSE) -> 2024 | I38: =YEAR(TODAY()) - H38 -> 2 | J38: NHQNXSP00141300B817600 | K38: Through LFP | L38: Transferred to Helen C. Roldan (FS-AD) | M38: For Transfer
D39: EPMPD | F39: FX506ll | G39: =VLOOKUP(F39,Data!$B$122:$C$135,2,FALSE) -> Asus | H39: =VLOOKUP(F39,Data!$B$122:$D$135,3,FALSE) -> 2021 | I39: =YEAR(TODAY()) - H39 -> 5 | J39: L8NRCX029715333 | K39: Through LFP | L39: Christian Harris T. Hernaez | M39: For RTS | N39: Deffective
D40: EPMPD | F40: ASPIRE 3 i5 | G40: =VLOOKUP(F40,Data!$B$122:$C$135,2,FALSE) -> Acer | H40: =VLOOKUP(F40,Data!$B$122:$D$135,3,FALSE) -> 2021 | I40: =YEAR(TODAY()) - H40 -> 5 | J40: NXHNSSP0029500422E7600 | K40: Through LFP | L40: Christian Harris T. Hernaez | M40: For RTS | N40: Deffective
...

Sheet Laptop
A1: No. | B1: Full Name | C1: Initials | D1: Division | E1: Position | F1: Model | G1: Brand | H1: Year Acquired/Transferred | I1: Years in service | J1: Serial Number | K1: Method of Procurement | L1: Current Custodian | M1: Remarks
A2: 1 | B2: Editha T. Ramos | C2: ETR | D2: EPRED | E2: Chief | F2: Predator Helios 300 | G2: =VLOOKUP(F2,Data!$B$122:$C$135,2,FALSE) -> Acer | H2: =VLOOKUP(F2,Data!$B$122:$D$135,3,FALSE) -> 2021 | I2: =YEAR(TODAY()) - H2 -> 5 | J2: NHQAUSP00111116A333400 | K2: Through LFP | L2: Editha T. Ramos
D3: EPRED | F3: Macbook Pro 13 Inch M2 | G3: =VLOOKUP(F3,Data!$B$122:$C$135,2,FALSE) -> Apple | H3: =VLOOKUP(F3,Data!$B$122:$D$135,3,FALSE) -> 2023 | I3: =YEAR(TODAY()) - H3 -> 3 | K3: Through LFP | L3: Editha T. Ramos
A4: 2 | B4: Roselle L. Ibuna | C4: RLI | D4: EPRED | E4: OIC-Supervising Science Research Specialist | F4: Mac Mini Desktop | G4: =VLOOKUP(F4,Data!$B$122:$C$135,2,FALSE) -> Apple | H4: =VLOOKUP(F4,Data!$B$122:$D$135,3,FALSE) -> 2022 | I4: =YEAR(TODAY()) - H4 -> 4 | J4: C07JC0AJQ6NY | K4: Through LFP | L4: Roselle L. Ibuna
D5: EPRED | F5: Macbook Pro 13 Inch M2 | G5: =VLOOKUP(F5,Data!$B$122:$C$135,2,FALSE) -> Apple | H5: =VLOOKUP(F5,Data!$B$122:$D$135,3,FALSE) -> 2023 | I5: =YEAR(TODAY()) - H5 -> 3 | J5: CJ7KXX9JKD | K5: Through LFP | L5: Roselle L. Ibuna
D6: EPRED | F6: TUF | G6: =VLOOKUP(F6,Data!$B$122:$C$135,2,FALSE) -> Asus | H6: =VLOOKUP(F6,Data!$B$122:$D$135,3,FALSE) -> 2020 | I6: =YEAR(TODAY()) - H6 -> 6 | J6: L8NRCX029705339 | K6: Through LFP | L6: Roselle L. Ibuna | M6: Reserve | N6: Transfer to EVIMD (c/o Jenny Ramos)
D7: EPRED | F7: Predator Helios 300 | G7: =VLOOKUP(F7,Data!$B$122:$C$135,2,FALSE) -> Acer | H7: =VLOOKUP(F7,Data!$B$122:$D$135,3,FALSE) -> 2021 | I7: =YEAR(TODAY()) - H7 -> 5 | J7: L8NRCX029705339 | K7: Through LFP | N7: Suzanne M. Pantaleon
A8: 3 | B8: Joan C. Escalona | C8: JCE | D8: EPRED | E8: Supervising Science Research Specialist | F8: Predator Helios 16 | G8: =VLOOKUP(F8,Data!$B$122:$C$135,2,FALSE) -> Acer | H8: =VLOOKUP(F8,Data!$B$122:$D$135,3,FALSE) -> 2024 | I8: =YEAR(TODAY()) - H8 -> 2 | J8: NHQNXSP00141300BAC7600 | K8: Through LFP | L8: Mary Ann M. Fernando
D9: EPRED | F9: Macbook Pro 13 Inch M2 | G9: =VLOOKUP(F9,Data!$B$122:$C$135,2,FALSE) -> Apple | H9: =VLOOKUP(F9,Data!$B$122:$D$135,3,FALSE) -> 2023 | I9: =YEAR(TODAY()) - H9 -> 3 | J9: MJL6KWYPVW | K9: Through LFP | L9: Joan C. Escalona
A10: 4 | B10: Steven Ivan G. Caiña | C10: SIGC | D10: EPRED | E10: OIC-Senior Science Research Specialist | F10: Macbook Pro 14 Inch M2 | G10: =VLOOKUP(F10,Data!$B$122:$C$135,2,FALSE) -> Apple | H10: =VLOOKUP(F10,Data!$B$122:$D$135,3,FALSE) -> 2023 | I10: =YEAR(TODAY()) - H10 -> 3 | J10: D6KCXF4R9D | K10: Through LFP | L10: Steven Ivan G. Caiña
D11: EPRED | F11: Predator Helios 300 | G11: =VLOOKUP(F11,Data!$B$122:$C$135,2,FALSE) -> Acer | H11: =VLOOKUP(F11,Data!$B$122:$D$135,3,FALSE) -> 2021 | I11: =YEAR(TODAY()) - H11 -> 5 | J11: NHQAUSPOO1111177763400 | K11: Through LFP | L11: Sheila C. Gadil
D12: EPRED | F12: Predator Helios 300 | G12: =VLOOKUP(F12,Data!$B$122:$C$135,2,FALSE) -> Acer | H12: =VLOOKUP(F12,Data!$B$122:$D$135,3,FALSE) -> 2021 | I12: =YEAR(TODAY()) - H12 -> 5 | J12: NHQAUSP0011111767D3400 | K12: Through LFP | L12: Steven Ivan G. Caiña | M12: For RTS
D13: EPRED | F13: Predator Helios 300 | G13: =VLOOKUP(F13,Data!$B$122:$C$135,2,FALSE) -> Acer | H13: =VLOOKUP(F13,Data!$B$122:$D$135,3,FALSE) -> 2021 | I13: =YEAR(TODAY()) - H13 -> 5 | J13: NHQAUSPOO11111720E3400 | K13: Through LFP | N13: Argy E. Gatdula
D14: EPRED | F14: Predator Helios 300 | G14: =VLOOKUP(F14,Data!$B$122:$C$135,2,FALSE) -> Acer | H14: =VLOOKUP(F14,Data!$B$122:$D$135,3,FALSE) -> 2021 | I14: =YEAR(TODAY()) - H14 -> 5 | J14: NHQC1SP002147275433400 | K14: Through LFP | L14: Benlie Mae B. Antonio
D15: EPRED | F15: Mac Mini Desktop | G15: =VLOOKUP(F15,Data!$B$122:$C$135,2,FALSE) -> Apple | H15: =VLOOKUP(F15,Data!$B$122:$D$135,3,FALSE) -> 2022 | I15: =YEAR(TODAY()) - H15 -> 4 | J15: 206NTJJ9X908 | K15: Through LFP | L15: Chester Syrill J. De Castro | M15: For Transfer
D16: EPRED | F16: TUF | G16: =VLOOKUP(F16,Data!$B$122:$C$135,2,FALSE) -> Asus | H16: =VLOOKUP(F16,Data!$B$122:$D$135,3,FALSE) -> 2020 | I16: =YEAR(TODAY()) - H16 -> 6 | J16: L8NRCX029725337 | K16: Through LFP | L16: Ara Jane C. Canaria
A17: 5 | B17: Aaron R. Premacio | C17: ARP | D17: EPRED | E17: Senior Science Research Specialist | F17: Predator Helios 16 | G17: =VLOOKUP(F17,Data!$B$122:$C$135,2,FALSE) -> Acer | H17: =VLOOKUP(F17,Data!$B$122:$D$135,3,FALSE) -> 2024 | I17: =YEAR(TODAY()) - H17 -> 2 | J17: NHQNXSP00141300C387600 | K17: Through LFP | L17: Aaron R. Premacio
D18: EPRED | F18: Predator Helios 300 | G18: =VLOOKUP(F18,Data!$B$122:$C$135,2,FALSE) -> Acer | H18: =VLOOKUP(F18,Data!$B$122:$D$135,3,FALSE) -> 2021 | I18: =YEAR(TODAY()) - H18 -> 5 | K18: Through LFP | N18: Michael Angelo O. Guarin
D19: EPRED | F19: TUF | G19: =VLOOKUP(F19,Data!$B$122:$C$135,2,FALSE) -> Asus | H19: =VLOOKUP(F19,Data!$B$122:$D$135,3,FALSE) -> 2020 | I19: =YEAR(TODAY()) - H19 -> 6 | J19: L8NRCX02972133B | K19: Through LFP | N19: Kristine Joy. B. Villaluz
A20: 6 | B20: Celedonio Tiu Salle | C20: CTS | D20: EPRED | E20: Senior Science Research Specialist | F20: Predator Helios 16 | G20: =VLOOKUP(F20,Data!$B$122:$C$135,2,FALSE) -> Acer | H20: =VLOOKUP(F20,Data!$B$122:$D$135,3,FALSE) -> 2024 | I20: =YEAR(TODAY()) - H20 -> 2 | J20: NHQNXSP00141300C097600 | K20: Through LFP | L20: Celedonio Tiu Salle
A21: 7 | B21: Erwin-Lou D. Peregrino | C21: EDP | D21: EPRED | E21: Science Research Specialist II | F21: Predator Helios 16 | G21: =VLOOKUP(F21,Data!$B$122:$C$135,2,FALSE) -> Acer | H21: =VLOOKUP(F21,Data!$B$122:$D$135,3,FALSE) -> 2024 | I21: =YEAR(TODAY()) - H21 -> 2 | J21: NHQNXSP00141300A5D7600 | K21: Through LFP | L21: Erwin-Lou D. Peregrino
D22: EPRED | F22: Predator Helios 16 | G22: =VLOOKUP(F22,Data!$B$122:$C$135,2,FALSE) -> Acer | H22: =VLOOKUP(F22,Data!$B$122:$D$135,3,FALSE) -> 2024 | I22: =YEAR(TODAY()) - H22 -> 2 | J22: NHQNXSP0014130097B7600 | K22: Through LFP | L22: James C. Francisco
A23: 8 | B23: Catherine C. Cadiz | C23: CCC | D23: EPRED | E23: Science Research Specialist II | F23: Predator Helios 16 | G23: =VLOOKUP(F23,Data!$B$122:$C$135,2,FALSE) -> Acer | H23: =VLOOKUP(F23,Data!$B$122:$D$135,3,FALSE) -> 2024 | I23: =YEAR(TODAY()) - H23 -> 2 | J23: NHQNXSP00141300BDE7600 | K23: Through LFP | L23: Catherine C. Cadiz
D24: EPRED | F24: Macbook Pro 13 Inch M2 | G24: =VLOOKUP(F24,Data!$B$122:$C$135,2,FALSE) -> Apple | H24: =VLOOKUP(F24,Data!$B$122:$D$135,3,FALSE) -> 2023 | I24: =YEAR(TODAY()) - H24 -> 3 | K24: Through LFP | L24: Catherine C. Cadiz
A25: 9 | B25: Chesca Mie A. Gaduyon | C25: CMAG | D25: EPRED | E25: Science Research Specialist II | F25: Macbook Pro 13 Inch M2 | G25: =VLOOKUP(F25,Data!$B$122:$C$135,2,FALSE) -> Apple | H25: =VLOOKUP(F25,Data!$B$122:$D$135,3,FALSE) -> 2023 | I25: =YEAR(TODAY()) - H25 -> 3 | J25: CWDKH2WLT6 | K25: Through LFP | L25: Chesca Mie A. Gaduyon
A26: 10 | B26: Marienelle S. Santos | C26: MSS | D26: EPRED | E26: Science Research Specialist II | F26: Macbook Pro 13 Inch M2 | G26: =VLOOKUP(F26,Data!$B$122:$C$135,2,FALSE) -> Apple | H26: =VLOOKUP(F26,Data!$B$122:$D$135,3,FALSE) -> 2023 | I26: =YEAR(TODAY()) - H26 -> 3 | J26: SHXJLD2TQ1WFV | K26: Through LFP | L26: Marienelle S. Santos
D27: EPRED | F27: Macbook Air 13 inch M1 | G27: =VLOOKUP(F27,Data!$B$122:$C$135,2,FALSE) -> Apple | H27: =VLOOKUP(F27,Data!$B$122:$D$135,3,FALSE) -> 2022 | I27: =YEAR(TODAY()) - H27 -> 4 | K27: Through LFP | N27: Hannah Isabel L. Cumpas
A28: 11 | B28: Daniel Vincent P. De Guzman | C28: DVDG | D28: EPRED | E28: Science Research Specialist II | F28: Predator Helios 16 | G28: =VLOOKUP(F28,Data!$B$122:$C$135,2,FALSE) -> Acer | H28: =VLOOKUP(F28,Data!$B$122:$D$135,3,FALSE) -> 2024 | I28: =YEAR(TODAY()) - H28 -> 2 | J28: NHQNXSP00141300C8C7600 | K28: Through LFP | L28: Daniel Vincent P. De Guzman
A29: 12 | B29: Von Jari A. Anievas | C29: VJA | D29: EPRED | E29: Science Research Specialist I | F29: Predator Helios 16 | G29: =VLOOKUP(F29,Data!$B$122:$C$135,2,FALSE) -> Acer | H29: =VLOOKUP(F29,Data!$B$122:$D$135,3,FALSE) -> 2024 | I29: =YEAR(TODAY()) - H29 -> 2 | L29: Von Jari A. Anievas
A30: 12 | B30: Chester Syrill J. De Castro | C30: CSJDC | D30: EPRED | E30: Science Research Specialist I | F30: Predator Helios 300 | G30: =VLOOKUP(F30,Data!$B$122:$C$135,2,FALSE) -> Acer | H30: =VLOOKUP(F30,Data!$B$122:$D$135,3,FALSE) -> 2021 | I30: =YEAR(TODAY()) - H30 -> 5 | J30: NHQAUSP001111167B03400 | K30: Through LFP | L30: Chester Syrill J. De Castro
A31: 13 | B31: Marvin B. Bahia | C31: MBB | D31: EPRED | E31: Science Research Specialist I | F31: Predator Helios 300 | G31: =VLOOKUP(F31,Data!$B$122:$C$135,2,FALSE) -> Acer | H31: =VLOOKUP(F31,Data!$B$122:$D$135,3,FALSE) -> 2021 | I31: =YEAR(TODAY()) - H31 -> 5 | J31: NHQAUSP001111172DB3400 | K31: Through LFP | L31: Marvin B. Bahia
A32: 14 | B32: Christine Joy M. Lamzon | C32: CJML | D32: EPRED | E32: Administrative Aide VI | F32: Predator Helios 16 | G32: =VLOOKUP(F32,Data!$B$122:$C$135,2,FALSE) -> Acer | H32: =VLOOKUP(F32,Data!$B$122:$D$135,3,FALSE) -> 2024 | I32: =YEAR(TODAY()) - H32 -> 2 | J32: NHQNXSP001413009A37600 | K32: Through LFP | L32: Christine Joy M. Lamzon
A33: 17 | B33: Daniel Collin G. Jornales | C33: DCGJ | D33: EPMPD | E33: Chief Science Research Specialist | F33: Macbook Pro 14 Inch M2 | G33: =VLOOKUP(F33,Data!$B$122:$C$135,2,FALSE) -> Apple | H33: =VLOOKUP(F33,Data!$B$122:$D$135,3,FALSE) -> 2023 | I33: 1 | J33: CGQJ1YYVKC | K33: Through LFP | L33: Hans Christer A. Arcilla
D34: EPMPD | F34: Predator Helios 16 | G34: =VLOOKUP(F34,Data!$B$122:$C$135,2,FALSE) -> Acer | H34: =VLOOKUP(F34,Data!$B$122:$D$135,3,FALSE) -> 2024 | I34: =YEAR(TODAY()) - H34 -> 2 | J34: NHQNXSP00141300AD77600 | K34: Through LFP | N34: Mark Adrian A. Aclon
A35: 18 | B35: Christian Harris T. Hernaez | C35: CHTH | D35: EPMPD | E35: OIC Supervising Science Research Specialist | F35: Macbook Pro 13 Inch M2 | G35: =VLOOKUP(F35,Data!$B$122:$C$135,2,FALSE) -> Apple | H35: =VLOOKUP(F35,Data!$B$122:$D$135,3,FALSE) -> 2023 | I35: =YEAR(TODAY()) - H35 -> 3 | J35: XHW7KY7CQV | K35: Through LFP | L35: Christian Harris T. Hernaez
D36: EPMPD | F36: Macbook Air 13 inch 2017 | G36: =VLOOKUP(F36,Data!$B$122:$C$135,2,FALSE) -> Apple | H36: =VLOOKUP(F36,Data!$B$122:$D$135,3,FALSE) -> 2017 | I36: =YEAR(TODAY()) - H36 -> 9 | J36: FVFY486Z1WK | K36: Through LFP | L36: Christian Harris T. Hernaez | M36: For Transfer
D37: EPMPD | F37: Predator Helios 16 | G37: =VLOOKUP(F37,Data!$B$122:$C$135,2,FALSE) -> Acer | H37: =VLOOKUP(F37,Data!$B$122:$D$135,3,FALSE) -> 2024 | I37: =YEAR(TODAY()) - H37 -> 2 | J37: NHQNXSP00141300B817600 | K37: Through LFP | M37: For Transfer | N37: Transferred to Helen C. Roldan (FS-AD)
D38: EPMPD | F38: FX506ll | G38: =VLOOKUP(F38,Data!$B$122:$C$135,2,FALSE) -> Asus | H38: =VLOOKUP(F38,Data!$B$122:$D$135,3,FALSE) -> 2021 | I38: =YEAR(TODAY()) - H38 -> 5 | J38: L8NRCX029715333 | K38: Through LFP | L38: Christian Harris T. Hernaez | M38: For RTS | N38: Deffective
D39: EPMPD | F39: ASPIRE 3 i5 | G39: =VLOOKUP(F39,Data!$B$122:$C$135,2,FALSE) -> Acer | H39: =VLOOKUP(F39,Data!$B$122:$D$135,3,FALSE) -> 2021 | I39: =YEAR(TODAY()) - H39 -> 5 | J39: NXHNSSP0029500422E7600 | K39: Through LFP | L39: Christian Harris T. Hernaez | M39: For RTS | N39: Deffective
A40: 19 | B40: Dave Angelo T. Cabalteja | C40: DATC | D40: EPMPD | E40: Science Research Specialist II | F40: Predator Helios 300 | G40: =VLOOKUP(F40,Data!$B$122:$C$135,2,FALSE) -> Acer | H40: =VLOOKUP(F40,Data!$B$122:$D$135,3,FALSE) -> 2021 | I40: =YEAR(TODAY()) - H40 -> 5 | J40: NHQAUSPOO111117A733400 | K40: Through LFP | M40: For Transfer
...

Sheet Tablet
A1: No. | B1: Full Name | C1: Initials | D1: Division | E1: Position | F1: Model | G1: Brand | H1: Year Acquired/ Transferred | I1: Years in service | J1: Serial Number | K1: Method of Procurement | L1: Current Custodian | M1: Remarks
A2: 1 | B2: Editha T. Ramos | C2: ETR | D2: EPRED | E2: Chief | F2: iPad | G2: =VLOOKUP(F2,Data!$B$140:$C$144,2,FALSE) -> Apple | H2: =VLOOKUP(F2,Data!$B$140:$D$144,3,FALSE) -> 2023 | I2: =YEAR(TODAY()) - H2 -> 3 | L2: Editha T. Ramos
D3: EPRED | F3: Xiaomi Pad 6 | G3: =VLOOKUP(F3,Data!$B$140:$C$144,2,FALSE) -> Xiaomi | H3: =VLOOKUP(F3,Data!$B$140:$D$144,3,FALSE) -> 2023 | I3: =YEAR(TODAY()) - H3 -> 3 | L3: John Jomari M. Garcia
D4: EPRED | F4: Xiaomi Pad 6 | G4: =VLOOKUP(F4,Data!$B$140:$C$144,2,FALSE) -> Xiaomi | H4: =VLOOKUP(F4,Data!$B$140:$D$144,3,FALSE) -> 2023 | I4: =YEAR(TODAY()) - H4 -> 3 | L4: Von Jari Anievas
A5: 2 | B5: Roselle L. Ibuna | C5: RLI | D5: EPRED | E5: OIC-Supervising Science Research Specialist | F5: iPad | G5: =VLOOKUP(F5,Data!$B$140:$C$144,2,FALSE) -> Apple | H5: =VLOOKUP(F5,Data!$B$140:$D$144,3,FALSE) -> 2023 | I5: =YEAR(TODAY()) - H5 -> 3 | L5: Roselle L. Ibuna
D6: EPRED | F6: Xiaomi Pad 6 | G6: =VLOOKUP(F6,Data!$B$140:$C$144,2,FALSE) -> Xiaomi | H6: =VLOOKUP(F6,Data!$B$140:$D$144,3,FALSE) -> 2023 | I6: =YEAR(TODAY()) - H6 -> 3 | L6: Merielle T. Maranan
A7: 3 | B7: Joan C. Escalona | C7: JCE | D7: EPRED | E7: Supervising Science Research Specialist | F7: iPad | G7: =VLOOKUP(F7,Data!$B$140:$C$144,2,FALSE) -> Apple | H7: =VLOOKUP(F7,Data!$B$140:$D$144,3,FALSE) -> 2023 | I7: =YEAR(TODAY()) - H7 -> 3 | L7: Joan C. Escalona
A8: 4 | B8: Eleanor R. Hainto | C8: ERH | D8: EPRED | E8: Science Research Specialist II | F8: Xiaomi Pad 6 | G8: =VLOOKUP(F8,Data!$B$140:$C$144,2,FALSE) -> Xiaomi | H8: =VLOOKUP(F8,Data!$B$140:$D$144,3,FALSE) -> 2023 | I8: =YEAR(TODAY()) - H8 -> 3 | L8: Eleanor R. Hainto
A9: 5 | B9: Steven Ivan G. Caiña | C9: SIGC | D9: EPRED | E9: Science Research Specialist II | F9: iPad | G9: =VLOOKUP(F9,Data!$B$140:$C$144,2,FALSE) -> Apple | H9: =VLOOKUP(F9,Data!$B$140:$D$144,3,FALSE) -> 2023 | I9: =YEAR(TODAY()) - H9 -> 3 | L9: Steven Ivan G. Caiña
D10: EPRED | F10: Xiaomi Pad 6 (Last Batch) | G10: =VLOOKUP(F10,Data!$B$140:$C$144,2,FALSE) -> Xiaomi | H10: =VLOOKUP(F10,Data!$B$140:$D$144,3,FALSE) -> 2024 | I10: =YEAR(TODAY()) - H10 -> 2 | J10: 47859/04TM00697 | L10: Ara Jane C. Canaria
D11: EPRED | F11: Xiaomi Pad 6 (Last Batch) | G11: =VLOOKUP(F11,Data!$B$140:$C$144,2,FALSE) -> Xiaomi | H11: =VLOOKUP(F11,Data!$B$140:$D$144,3,FALSE) -> 2024 | I11: =YEAR(TODAY()) - H11 -> 2 | J11: 47780/04PU02866 | L11: Benlie Mae B. Antonio
D12: EPRED | F12: Xiaomi Pad 6 (Last Batch) | G12: =VLOOKUP(F12,Data!$B$140:$C$144,2,FALSE) -> Xiaomi | H12: =VLOOKUP(F12,Data!$B$140:$D$144,3,FALSE) -> 2024 | I12: =YEAR(TODAY()) - H12 -> 2 | J12: 47780/04PF00622 | M12: Suzanne M. Pantaleon
D13: EPRED | F13: Xiaomi Pad 6 (Last Batch) | G13: =VLOOKUP(F13,Data!$B$140:$C$144,2,FALSE) -> Xiaomi | H13: =VLOOKUP(F13,Data!$B$140:$D$144,3,FALSE) -> 2024 | I13: =YEAR(TODAY()) - H13 -> 2 | M13: Hannah Isabel L. Cumpas
A14: 6 | B14: Aaron R. Premacio | C14: ARP | D14: EPRED | E14: Science Research Specialist II | F14: Xiaomi Pad 6 | G14: =VLOOKUP(F14,Data!$B$140:$C$144,2,FALSE) -> Xiaomi | H14: =VLOOKUP(F14,Data!$B$140:$D$144,3,FALSE) -> 2023 | I14: =YEAR(TODAY()) - H14 -> 3 | L14: Aaron R. Premacio
A15: 7 | B15: Celedonio Tiu Salle | C15: CTS | D15: EPRED | E15: Science Research Specialist II | F15: Xiaomi Pad 6 (Last Batch) | G15: =VLOOKUP(F15,Data!$B$140:$C$144,2,FALSE) -> Xiaomi | H15: =VLOOKUP(F15,Data!$B$140:$D$144,3,FALSE) -> 2024 | I15: =YEAR(TODAY()) - H15 -> 2 | L15: Celedonio Tiu Salle
A16: 8 | B16: Erwin-Lou D. Peregrino | C16: EDP | D16: EPRED | E16: Science Research Specialist II | F16: Xiaomi Pad 6 | G16: =VLOOKUP(F16,Data!$B$140:$C$144,2,FALSE) -> Xiaomi | H16: =VLOOKUP(F16,Data!$B$140:$D$144,3,FALSE) -> 2023 | I16: =YEAR(TODAY()) - H16 -> 3 | L16: Erwin-Lou D. Peregrino
D17: EPRED | F17: Xiaomi Pad 6 | G17: =VLOOKUP(F17,Data!$B$140:$C$144,2,FALSE) -> Xiaomi | H17: =VLOOKUP(F17,Data!$B$140:$D$144,3,FALSE) -> 2023 | I17: =YEAR(TODAY()) - H17 -> 3 | L17: James C. Francisco
A18: 9 | B18: Catherine C. Cadiz | C18: CCC | D18: EPRED | E18: Science Research Specialist II | F18: Xiaomi Pad 6 | G18: =VLOOKUP(F18,Data!$B$140:$C$144,2,FALSE) -> Xiaomi | H18: =VLOOKUP(F18,Data!$B$140:$D$144,3,FALSE) -> 2023 | I18: =YEAR(TODAY()) - H18 -> 3 | L18: Catherine C. Cadiz
A19: 10 | B19: Chesca Mie A. Gaduyon | C19: CMAG | D19: EPRED | E19: Science Research Specialist II | F19: Xiaomi Pad 6 | G19: =VLOOKUP(F19,Data!$B$140:$C$144,2,FALSE) -> Xiaomi | H19: =VLOOKUP(F19,Data!$B$140:$D$144,3,FALSE) -> 2023 | I19: =YEAR(TODAY()) - H19 -> 3 | J19: 47795/K3VQ02244 | L19: Hannah Isabel L. Cumpas
D20: EPRED | F20: Samsung Galaxy Tab | G20: =VLOOKUP(F20,Data!$B$140:$C$144,2,FALSE) -> Samsung | H20: =VLOOKUP(F20,Data!$B$140:$D$144,3,FALSE) -> 2024 | I20: =YEAR(TODAY()) - H20 -> 2 | J20: R52WC04FCJT | L20: Chesca Mie A. Gaduyon
A21: 11 | B21: Marienelle S. Santos | C21: MSS | D21: EPRED | E21: Science Research Specialist II | F21: Xiaomi Pad 6 | G21: =VLOOKUP(F21,Data!$B$140:$C$144,2,FALSE) -> Xiaomi | H21: =VLOOKUP(F21,Data!$B$140:$D$144,3,FALSE) -> 2023 | I21: =YEAR(TODAY()) - H21 -> 3 | L21: Marienelle S. Santos
D22: EPRED | F22: Xiaomi Pad 6 | G22: =VLOOKUP(F22,Data!$B$140:$C$144,2,FALSE) -> Xiaomi | H22: =VLOOKUP(F22,Data!$B$140:$D$144,3,FALSE) -> 2023 | I22: =YEAR(TODAY()) - H22 -> 3 | L22: Sheila C. Gadil
A23: 12 | B23: Daniel Vincent P. De Guzman | C23: DVDG | D23: EPRED | E23: Science Research Specialist II | F23: Xiaomi Pad 6 | G23: =VLOOKUP(F23,Data!$B$140:$C$144,2,FALSE) -> Xiaomi | H23: =VLOOKUP(F23,Data!$B$140:$D$144,3,FALSE) -> 2023 | I23: =YEAR(TODAY()) - H23 -> 3 | L23: Daniel Vincent P. De Guzman
D24: EPRED | F24: Xiaomi Pad 6 | G24: =VLOOKUP(F24,Data!$B$140:$C$144,2,FALSE) -> Xiaomi | H24: =VLOOKUP(F24,Data!$B$140:$D$144,3,FALSE) -> 2023 | I24: =YEAR(TODAY()) - H24 -> 3 | L24: Mary Ann Fernando
A25: 13 | B25: Chester Syrill J. De Castro | C25: CSJDC | D25: EPRED | E25: Science Research Specialist I | F25: Xiaomi Pad 6 (Last Batch) | G25: =VLOOKUP(F25,Data!$B$140:$C$144,2,FALSE) -> Xiaomi | H25: =VLOOKUP(F25,Data!$B$140:$D$144,3,FALSE) -> 2024 | I25: =YEAR(TODAY()) - H25 -> 2 | L25: Chester Syrill J. De Castro
A26: 14 | B26: Marvin B. Bahia | C26: MBB | D26: EPRED | E26: Science Research Specialist I | F26: Xiaomi Pad 6 (Last Batch) | G26: =VLOOKUP(F26,Data!$B$140:$C$144,2,FALSE) -> Xiaomi | H26: =VLOOKUP(F26,Data!$B$140:$D$144,3,FALSE) -> 2024 | I26: =YEAR(TODAY()) - H26 -> 2 | L26: Marvin B. Bahia
A27: 15 | B27: Christine Joy M. Lamzon | C27: CJML | D27: EPRED | E27: Administrative Aide VI | F27: Xiaomi Pad 6 | G27: =VLOOKUP(F27,Data!$B$140:$C$144,2,FALSE) -> Xiaomi | H27: =VLOOKUP(F27,Data!$B$140:$D$144,3,FALSE) -> 2023 | I27: =YEAR(TODAY()) - H27 -> 3 | J27: 47843/K3U400176 | L27: Christine Joy M. Lamzon
A28: 16 | B28: Daniel Collin G. Jornales | C28: DCGJ | D28: EPMPD | E28: Chief Science Research Specialist | F28: Samsung Galaxy Tab | G28: =VLOOKUP(F28,Data!$B$140:$C$144,2,FALSE) -> Samsung | H28: =VLOOKUP(F28,Data!$B$140:$D$144,3,FALSE) -> 2024 | I28: =YEAR(TODAY()) - H28 -> 2
A29: 17 | B29: Christian Harris T. Hernaez | C29: CHTH | D29: EPMPD | E29: OIC Supervising Science Research Specialist | F29: Xiaomi Pad 6 | G29: =VLOOKUP(F29,Data!$B$140:$C$144,2,FALSE) -> Xiaomi | H29: =VLOOKUP(F29,Data!$B$140:$D$144,3,FALSE) -> 2023 | I29: =YEAR(TODAY()) - H29 -> 3 | L29: Hans Christer A. Arcilla
A30: 18 | B30: Jerick Kuh D. Nalaunan | C30: JKDN | D30: EPMPD | E30: Senior Science Research Specialist | F30: Xiaomi Pad 6 | G30: =VLOOKUP(F30,Data!$B$140:$C$144,2,FALSE) -> Xiaomi | H30: =VLOOKUP(F30,Data!$B$140:$D$144,3,FALSE) -> 2023 | I30: =YEAR(TODAY()) - H30 -> 3
A31: 19 | B31: Mara Camille C. Galos | C31: MCCG | D31: EPMPD | E31: Science Research Specialist II | F31: Xiaomi Pad 6 | G31: =VLOOKUP(F31,Data!$B$140:$C$144,2,FALSE) -> Xiaomi | H31: =VLOOKUP(F31,Data!$B$140:$D$144,3,FALSE) -> 2023 | I31: =YEAR(TODAY()) - H31 -> 3
A32: 20 | B32: Dave Angelo T. Cabalteja | C32: DATC | D32: EPMPD | E32: Science Research Specialist II | F32: Xiaomi Pad 6 | G32: =VLOOKUP(F32,Data!$B$140:$C$144,2,FALSE) -> Xiaomi | H32: =VLOOKUP(F32,Data!$B$140:$D$144,3,FALSE) -> 2023 | I32: =YEAR(TODAY()) - H32 -> 3
A33: 21 | B33: Vittorio Leif Ericson J. Santos | C33: VLEJS | D33: EPMPD | E33: Science Research Specialist II | F33: Xiaomi Pad 6 | G33: =VLOOKUP(F33,Data!$B$140:$C$144,2,FALSE) -> Xiaomi | H33: =VLOOKUP(F33,Data!$B$140:$D$144,3,FALSE) -> 2023 | I33: =YEAR(TODAY()) - H33 -> 3
A34: 22 | B34: Mary Mae C. Hernandez | C34: MMCH | D34: EPMPD | E34: Science Research Specialist II | F34: Xiaomi Pad 6 | G34: =VLOOKUP(F34,Data!$B$140:$C$144,2,FALSE) -> Xiaomi | H34: =VLOOKUP(F34,Data!$B$140:$D$144,3,FALSE) -> 2023 | I34: =YEAR(TODAY()) - H34 -> 3
A35: 23 | B35: Mark Jezekiah O. Abalos | C35: MJOA | D35: EPMPD | E35: Science Research Specialist I | F35: Samsung Galaxy Tab | G35: =VLOOKUP(F35,Data!$B$140:$C$144,2,FALSE) -> Samsung | H35: =VLOOKUP(F35,Data!$B$140:$D$144,3,FALSE) -> 2024 | I35: =YEAR(TODAY()) - H35 -> 2
A36: 24 | B36: Marivic P. Pajarillo | C36: MPP | D36: EPMPD | E36: Administrative III | F36: Xiaomi Pad 6 | G36: =VLOOKUP(F36,Data!$B$140:$C$144,2,FALSE) -> Xiaomi | H36: =VLOOKUP(F36,Data!$B$140:$D$144,3,FALSE) -> 2023 | I36: =YEAR(TODAY()) - H36 -> 3
A37: 26 | B37: Hans Christer A. Arcilla | C37: HCAA | D37: EPMPD | E37: Science Research Specialist I | F37: Xiaomi Pad 6 (Last Batch) | G37: xiaomi | H37: 2025 | I37: 1 | J37: 62779/05QD00365
B38: Dorella Maye T. Perlas | C38: DMTP | D38: EPMPD | E38: Senior Science Research Specialist | F38: Xiaomi Pad 6 | G38: Xiaomi | H38: 2023 | I38: =YEAR(TODAY()) - H38 -> 3 | J38: 47780|K3WC00814
A39: 27 | B39: Jimwel B. Balunday | C39: JBB | D39: EPSMD | E39: Chief | F39: iPad | G39: =VLOOKUP(F39,Data!$B$140:$C$144,2,FALSE) -> Apple | H39: =VLOOKUP(F39,Data!$B$140:$D$144,3,FALSE) -> 2023 | I39: =YEAR(TODAY()) - H39 -> 3 | L39: Angela Maureen Panapanaan
A40: 29 | B40: Anabel M. Elmaga | C40: AME | D40: EPSMD | E40: SR. SRS | F40: Xiaomi Pad 6 | G40: =VLOOKUP(F40,Data!$B$140:$C$144,2,FALSE) -> Xiaomi | H40: =VLOOKUP(F40,Data!$B$140:$D$144,3,FALSE) -> 2023 | I40: =YEAR(TODAY()) - H40 -> 3 | J40: 47854/K3XN00513 | L40: Anabel M. Elmaga
...

Sheet Drone
A1: No. | B1: Full Name | C1: Initials | D1: Division | E1: Position | F1: Model | G1: Brand | H1: Year Acquired/ Transferred | I1: Years in service | J1: Serial Number | K1: Method of Procurement | L1: Current Custodian | M1: Remarks
A2: 1 | B2: Editha T. Ramos | C2: ETR | D2: EPRED | E2: Chief
A3: 2 | B3: Roselle L. Ibuna | C3: RLI | D3: EPRED | E3: OIC-Supervising Science Research Specialist
A4: 3 | B4: Joan C. Escalona | C4: JCE | D4: EPRED | E4: Supervising Science Research Specialist
A5: 4 | B5: Eleanor R. Hainto | C5: ERH | D5: EPRED | E5: Science Research Specialist II
A6: 5 | B6: Steven Ivan G. Caiña | C6: SIGC | D6: EPRED | E6: Science Research Specialist II
A7: 6 | B7: Aaron R. Premacio | C7: ARP | D7: EPRED | E7: Science Research Specialist II
A8: 7 | B8: Celedonio Tiu Salle | C8: CTS | D8: EPRED | E8: Science Research Specialist II
A9: 8 | B9: Erwin-Lou D. Peregrino | C9: EDP | D9: EPRED | E9: Science Research Specialist II
A10: 9 | B10: Catherine C. Cadiz | C10: CCC | D10: EPRED | E10: Science Research Specialist II
A11: 10 | B11: Chesca Mie A. Gaduyon | C11: CMAG | D11: EPRED | E11: Science Research Specialist II
A12: 11 | B12: Marienelle S. Santos | C12: MSS | D12: EPRED | E12: Science Research Specialist II
A13: 12 | B13: Daniel Vincent P. De Guzman | C13: DVDG | D13: EPRED | E13: Science Research Specialist II
... A27: 26 | B27: Mary Grace Q. Razonable | C27: MGQR | D27: EPMPD | E27: Science Research Specialist I
A28: 27 | B28: Hans Christer A. Arcilla | C28: HCAA | D28: EPMPD | E28: Science Research Specialist I | F28: AIR 39 | G28: DJI | H28: 2025 | I28: 1 | J28: 1581F895C25180079N4M | L28: Daniel Collin G. Jornales
A29: 27 | B29: Mark Jezekiah O. Abalos | C29: MJOA | D29: EPMPD | E29: Science Research Specialist I
A30: 28 | B30: Marivic P. Pajarillo | C30: MPP | D30: EPMPD | E30: Administrative III
A31: 29 | B31: Jimwel B. Balunday | C31: JBB | D31: EPSMD | E31: Chief
A32: 30 | B32: Cynthia P.J Mañalac | C32: CPJM | D32: EPSMD | E32: Supervising SRS
A33: 31 | B33: Anabel M. Elmaga | C33: AME | D33: EPSMD | E33: SR. SRS
A34: 32 | B34: Victorino Getalado Jr. | C34: VGJ | D34: EPSMD | E34: SR. SRS
A35: 33 | B35: Marc M. Martinez | C35: MMM | D35: EPSMD | E35: SR. SRS
A36: 34 | B36: Sir Roland C. Basco | C36: SRCB | D36: EPSMD | E36: SR. SRS
A37: 35 | B37: Raziel Angela Lizardo | C37: RAL | D37: EPSMD | E37: SRS II
A38: 36 | B38: Dorella Maye T. Perlas | C38: DMTP | D38: EPSMD | E38: SRS II
A39: 37 | B39: John Levi M. Mecca | C39: JLMM | D39: EPSMD | E39: SRS II
A40: 38 | B40: Ingrid Faye P. Calayag | C40: IFPC | D40: EPSMD | E40: SRS II
... A88: 86 | B88: Camilo B. Dadia | C88: CBD | D88: OD | E88: Administrative Aide II

Sheet Camera
A1: No. | B1: Full Name | C1: Initials | D1: Division | E1: Position | F1: Model | G1: Brand | H1: Year Acquired/ Transferred | I1: Years in service | J1: Serial Number | K1: Method of Procurement | L1: Current Custodian | M1: Remarks
A2: 1 | B2: Editha T. Ramos | C2: ETR | D2: EPRED | E2: Chief
A3: 2 | B3: Roselle L. Ibuna | C3: RLI | D3: EPRED | E3: OIC-Supervising Science Research Specialist | F3: GoPro Hero 12 Black Creator | G3: =VLOOKUP(F3,Data!$B$147:$D$147,2,FALSE) -> GoPro | H3: =VLOOKUP(F3,Data!$B$147:$D$147,3,FALSE) -> 2024 | I3: =YEAR(TODAY()) - H3 -> 2 | J3: C3501325501968 | L3: Roselle L. Ibuna
A4: 3 | B4: Joan C. Escalona | C4: JCE | D4: EPRED | E4: Supervising Science Research Specialist | F4: GoPro Hero 12 Black Creator | G4: =VLOOKUP(F4,Data!$B$147:$D$147,2,FALSE) -> GoPro | H4: =VLOOKUP(F4,Data!$B$147:$D$147,3,FALSE) -> 2024 | I4: =YEAR(TODAY()) - H4 -> 2 | J4: C3501325493124 | L4: Joan C. Escalona
A5: 4 | B5: Eleanor R. Hainto | C5: ERH | D5: EPRED | E5: Science Research Specialist II
A6: 5 | B6: Steven Ivan G. Caiña | C6: SIGC | D6: EPRED | E6: Science Research Specialist II | F6: GoPro Hero 12 Black Creator | G6: =VLOOKUP(F6,Data!$B$147:$D$147,2,FALSE) -> GoPro | H6: =VLOOKUP(F6,Data!$B$147:$D$147,3,FALSE) -> 2024 | I6: =YEAR(TODAY()) - H6 -> 2 | J6: C3501325491236 | L6: Steven Ivan G. Caiña
F7: GoPro | G7: GoPro | H7: 2023 | I7: =YEAR(TODAY()) - H7 -> 3 | L7: Steven Ivan G. Caiña
F8: GoPro | G8: GoPro | H8: 2023 | I8: =YEAR(TODAY()) - H8 -> 3 | L8: Steven Ivan G. Caiña
F9: Profesional Camera | G9: Nikon | L9: Steven Ivan G. Caiña
F10: Drone | L10: Steven Ivan G. Caiña
A11: 6 | B11: Aaron R. Premacio | C11: ARP | D11: EPRED | E11: Science Research Specialist II
A12: 7 | B12: Celedonio Tiu Salle | C12: CTS | D12: EPRED | E12: Science Research Specialist II | F12: GoPro Hero 12 Black Creator | G12: =VLOOKUP(F12,Data!$B$147:$D$147,2,FALSE) -> GoPro | H12: =VLOOKUP(F12,Data!$B$147:$D$147,3,FALSE) -> 2024 | I12: =YEAR(TODAY()) - H12 -> 2 | J12: C3501325491957 | L12: Celedonio Tiu Salle
A13: 8 | B13: Erwin-Lou D. Peregrino | C13: EDP | D13: EPRED | E13: Science Research Specialist II
A14: 9 | B14: Catherine C. Cadiz | C14: CCC | D14: EPRED | E14: Science Research Specialist II
A15: 10 | B15: Chesca Mie A. Gaduyon | C15: CMAG | D15: EPRED | E15: Science Research Specialist II | F15: GoPro Hero 12 Black Creator | G15: =VLOOKUP(F15,Data!$B$147:$D$147,2,FALSE) -> GoPro | H15: =VLOOKUP(F15,Data!$B$147:$D$147,3,FALSE) -> 2024 | I15: =YEAR(TODAY()) - H15 -> 2 | J15: C3501325503702 | L15: Chesca Mie A. Gaduyon
A16: 11 | B16: Marienelle S. Santos | C16: MSS | D16: EPRED | E16: Science Research Specialist II
A17: 12 | B17: Daniel Vincent P. De Guzman | C17: DVDG | D17: EPRED | E17: Science Research Specialist II
A18: 13 | B18: Rodger C. Pascual | C18: RCP | D18: EPRED | E18: Science Research Specialist I | F18: Profesional Camera | G18: Canon
A19: 14 | B19: Chester Syrill J. De Castro | C19: CSJDC | D19: EPRED | E19: Science Research Specialist I | F19: GoPro Hero 12 Black Creator | G19: =VLOOKUP(F19,Data!$B$147:$D$147,2,FALSE) -> GoPro | H19: =VLOOKUP(F19,Data!$B$147:$D$147,3,FALSE) -> 2024 | I19: =YEAR(TODAY()) - H19 -> 2 | J19: C3501325475208 | L19: Chester Syrill J. De Castro
A20: 15 | B20: Marvin B. Bahia | C20: MBB | D20: EPRED | E20: Science Research Specialist I
A21: 16 | B21: Christine Joy M. Lamzon | C21: CJML | D21: EPRED | E21: Administrative Aide VI
A22: 17 | B22: Daniel Collin G. Jornales | C22: DCGJ | D22: EPMPD | E22: Chief Science Research Specialist
A23: 18 | B23: Christian Harris T. Hernaez | C23: CHTH | D23: EPMPD | E23: OIC Supervising Science Research Specialist
A24: 19 | B24: Dave Angelo T. Cabalteja | C24: DATC | D24: EPMPD | E24: Science Research Specialist II
A25: 20 | B25: Vittorio Leif Ericson J. Santos | C25: VLEJS | D25: EPMPD | E25: Science Research Specialist II | F25: GoPro Hero 12 Black Creator | G25: =VLOOKUP(F25,Data!$B$147:$D$147,2,FALSE) -> GoPro | H25: =VLOOKUP(F25,Data!$B$147:$D$147,3,FALSE) -> 2024 | I25: =YEAR(TODAY()) - H25 -> 2 | J25: C3501325510598
F26: GoPro Hero 12 Black Creator | G26: =VLOOKUP(F26,Data!$B$147:$D$147,2,FALSE) -> GoPro | H26: =VLOOKUP(F26,Data!$B$147:$D$147,3,FALSE) -> 2024 | I26: =YEAR(TODAY()) - H26 -> 2 | J26: C3501325579869
F27: GoPro Hero 12 Black Creator | G27: =VLOOKUP(F27,Data!$B$147:$D$147,2,FALSE) -> GoPro | H27: =VLOOKUP(F27,Data!$B$147:$D$147,3,FALSE) -> 2024 | I27: =YEAR(TODAY()) - H27 -> 2 | J27: C3501325478311
A28: 21 | B28: Mary Mae C. Hernandez | C28: MMCH | D28: EPMPD | E28: Science Research Specialist II
A29: 22 | B29: Mark Jezekiah O. Abalos | C29: MJOA | D29: EPMPD | E29: Science Research Specialist I
A30: 23 | B30: Marivic P. Pajarillo | C30: MPP | D30: EPMPD | E30: Administrative III
B31: Dorella Maye T. Perlas | C31: DMTP | D31: EPMPD | E31: SR. SRS | F31: BODY MOUNTED ACTION CAMERA (PPE) - HERO 12 | G31: GoPro | H31: 2025 | J31: C3501325723591
F32: PROFESSIONAL CAMERA WITH LENS | G32: ALPHA A7R V BODY | H32: 2025 | J32: S013256871I
A33: 24 | B33: Hans Christer A. Arcilla | C33: HCAA | D33: EPMPD | E33: Science Research Specialist I | F33: BODY MOUNTED ACTION CAMERA (PPE) - HERO 12 | G33: GoPro | H33: 2025 | J33: C3501325801224 | L33: Jayvie A. Gaya
F34: PROFESSIONAL CAMERA WITH LENS | G34: ALPHA A7R V BODY | H34: 2025 | J34: S013256855K
A35: 24 | B35: Jimwel B. Balunday | C35: JBB | D35: EPSMD | E35: Chief | F35: GoPro Hero 12 Black Creator | G35: =VLOOKUP(F35,Data!$B$147:$D$147,2,FALSE) -> GoPro | H35: =VLOOKUP(F35,Data!$B$147:$D$147,3,FALSE) -> 2024 | I35: =YEAR(TODAY()) - H35 -> 2 | J35: C3501325480083
F36: GoPro Hero 12 Black Creator | G36: =VLOOKUP(F36,Data!$B$147:$D$147,2,FALSE) -> GoPro | H36: =VLOOKUP(F36,Data!$B$147:$D$147,3,FALSE) -> 2024 | I36: =YEAR(TODAY()) - H36 -> 2 | J36: C3501325504432
F37: GoPro Hero 12 Black Creator | G37: =VLOOKUP(F37,Data!$B$147:$D$147,2,FALSE) -> GoPro | H37: =VLOOKUP(F37,Data!$B$147:$D$147,3,FALSE) -> 2024 | I37: =YEAR(TODAY()) - H37 -> 2 | J37: C3501325592818
A38: 23 | B38: Cynthia P.J Mañalac | C38: CPJM | D38: EPSMD | E38: Supervising SRS
A39: 24 | B39: Anabel M. Elmaga | C39: AME | D39: EPSMD | E39: SR. SRS
A40: 25 | B40: Victorino Getalado Jr. | C40: VGJ | D40: EPSMD | E40: SR. SRS
...

Sheet Printer
A1: No. | B1: Division | C1: Model | D1: Brand | E1: Year Acquired/ Transferred | F1: Years in service | G1: Serial Number | H1: Method of Procurement | I1: Current Custodian | J1: Remarks
A2: 1 | B2: EPRED | C2: Color Lazer Jet Pro MFP M479fnw | D2: =VLOOKUP(C2,Data!B:C,2,FALSE) -> HP | J2: For RTS
A3: 2 | B3: EPRED | C3: Color Lazer Jet Enterprise MFP M681 | D3: =VLOOKUP(C3,Data!B:C,2,FALSE) -> HP
A4: 3 | B4: EPRED | C4: ECOYS M5526cdw | D4: =VLOOKUP(C4,Data!B:C,2,FALSE) -> KYOCERA
A5: 4 | B5: EPSMD | C5: LazerJet Pro 200 color M251n | D5: =VLOOKUP(C5,Data!B:C,2,FALSE) -> HP
A6: 5 | B6: EPSMD | C6: Color Lazer Jet Pro MFP M479fnw | D6: =VLOOKUP(C6,Data!B:C,2,FALSE) -> HP
A7: 6 | B7: EPSMD | C7: Color Lazer Jet Pro MFP M479fnw | D7: =VLOOKUP(C7,Data!B:C,2,FALSE) -> HP
A8: 7 | B8: EPSMD | C8: ECOYS M5526cdw | D8: =VLOOKUP(C8,Data!B:C,2,FALSE) -> KYOCERA
A9: 8 | B9: EPSMD | C9: WF-C579R | D9: =VLOOKUP(C9,Data!B:C,2,FALSE) -> EPSON
A10: 9 | B10: EPMPD | C10: 6053ci | D10: =VLOOKUP(C10,Data!B:C,2,FALSE) -> KYOCERA
A11: 10 | B11: AFETD | C11: L5290 | D11: =VLOOKUP(C11,Data!B:C,2,FALSE) -> EPSON
A12: 11 | B12: AFETD | C12: MFC-J3540DW | D12: =VLOOKUP(C12,Data!B:C,2,FALSE) -> BROTHER
A13: 12 | B13: EVIMD | C13: L5290 | D13: =VLOOKUP(C13,Data!B:C,2,FALSE) -> EPSON
A14: 13 | B14: EVIMD | C14: MFC-L8900CDW | D14: =VLOOKUP(C14,Data!B:C,2,FALSE) -> BROTHER
... A16: 15 | B16: NED | C16: ECOYS M5526cdw | D16: =VLOOKUP(C16,Data!B:C,2,FALSE) -> KYOCERA

Sheet Sheet1
L2: REPLACEMENT FOR 2026
B3: EUMB ICT SUMMARY 2025 | H3: EUMB ICT SUMMARY 2025 | L3: DIVISIONS | M3: REGULAR | Y3: LOCALLY FUNDED
B4: LAPTOP | H4: LAPTOP | M4: LAPTOP | P4: TABLET 1 | S4: TABLET 2 | V4: PRINTER 1 | Y4: LAPTOP | AB4: TABLET 1 | AE4: PRINTER 1 | AH4: PRINTER 2
B5: DIVISION | C5: 3 YEARS & BELOW | D5: ABOVE 3 YEARS | E5: FOR RELACEMENT | F5: TOTAL | H5: DIVISION | I5: INVENTORY | M5: Request | N5: Unit Cost | O5: Total | P5: Request | Q5: Unit Cost | R5: Total | S5: Request | T5: Unit Cost | U5: Total | V5: Request | W5: Unit Cost | X5: Total | Y5: Request | Z5: Unit Cost | AA5: Total | AB5: Request | AC5: Unit Cost | AD5: Total | AE5: Request | AF5: Unit Cost | AG5: Total | AH5: Request | AI5: Unit Cost | AJ5: Total
B6: EPRED | C6: 12 | D6: 8 | E6: =D6 -> 8 | F6: =C6+D6 -> 20 | H6: EPRED | I6: 20 | L6: EPRED | N6: 160000 | O6: =M6*N6 -> 0 | Q6: 90000 | R6: =P6*Q6 -> 0 | T6: 140000 | U6: =S6*T6 -> 0 | W6: 60000 | X6: =V6*W6 -> 0 | Y6: 3 | Z6: 160000 | AA6: =Y6*Z6 -> 480000 | AC6: 90000 | AD6: =AB6*AC6 -> 0 | AE6: 2 | AF6: 30000 | AG6: =AE6*AF6 -> 60000 | AH6: 1 | AI6: 60000 | AJ6: =AH6*AI6 -> 60000
B7: EPSMD | C7: 14 | D7: 6 | E7: 6 | F7: =C7+D7 -> 20 | H7: EPSMD | I7: 20 | L7: EPSMD | N7: 160000 | O7: =M7*N7 -> 0 | Q7: 90000 | R7: =P7*Q7 -> 0 | T7: 140000 | U7: =S7*T7 -> 0 | W7: 60000 | X7: =V7*W7 -> 0 | Y7: 3 | Z7: 160000 | AA7: =Y7*Z7 -> 480000 | AC7: 90000 | AD7: =AB7*AC7 -> 0 | AE7: 3 | AF7: 30000 | AG7: =AE7*AF7 -> 90000 | AH7: 2 | AI7: 60000 | AJ7: =AH7*AI7 -> 120000
B8: EPMPD | C8: 13 | D8: 8 | E8: 11 | F8: =C8+D8 -> 21 | H8: EPMPD | I8: 21 | L8: EPMPD | N8: 160000 | O8: =M8*N8 -> 0 | Q8: 90000 | R8: =P8*Q8 -> 0 | T8: 140000 | U8: =S8*T8 -> 0 | W8: 60000 | X8: =V8*W8 -> 0 | Y8: 3 | Z8: 160000 | AA8: =Y8*Z8 -> 480000 | AB8: 7 | AC8: 90000 | AD8: =AB8*AC8 -> 630000 | AF8: 30000 | AG8: =AE8*AF8 -> 0 | AI8: 60000 | AJ8: =AH8*AI8 -> 0
B9: AFETD | C9: 31 | D9: 8 | E9: 8 | F9: =C9+D9 -> 39 | H9: AFETD | I9: 39 | L9: AFETD | N9: 160000 | O9: =M9*N9 -> 0 | Q9: 90000 | R9: =P9*Q9 -> 0 | T9: 140000 | U9: =S9*T9 -> 0 | W9: 60000 | X9: =V9*W9 -> 0 | Z9: 160000 | AA9: =Y9*Z9 -> 0 | AB9: 4 | AC9: 90000 | AD9: =AB9*AC9 -> 360000 | AE9: 2 | AF9: 30000 | AG9: =AE9*AF9 -> 60000 | AI9: 60000 | AJ9: =AH9*AI9 -> 0
B10: EVIMD | C10: 12 | D10: 5 | E10: 5 | F10: =C10+D10 -> 17 | H10: EVIMD | I10: 17 | L10: EVIMD | M10: 1 | N10: 160000 | O10: =M10*N10 -> 160000 | P10: 6 | Q10: 90000 | R10: =P10*Q10 -> 540000 | T10: 140000 | U10: =S10*T10 -> 0 | V10: 1 | W10: 60000 | X10: =V10*W10 -> 60000 | Z10: 160000 | AA10: =Y10*Z10 -> 0 | AC10: 90000 | AD10: =AB10*AC10 -> 0 | AF10: 30000 | AG10: =AE10*AF10 -> 0 | AI10: 60000 | AJ10: =AH10*AI10 -> 0
B11: NED | C11: 11 | D11: 2 | E11: 1 | F11: =C11+D11 -> 13 | H11: NED | I11: 13 | L11: NED | M11: 12 | N11: 160000 | O11: =M11*N11 -> 1920000 | Q11: 90000 | R11: =P11*Q11 -> 0 | S11: 12 | T11: 140000 | U11: =S11*T11 -> 1680000 | V11: 2 | W11: 60000 | X11: =V11*W11 -> 120000 | Z11: 160000 | AA11: =Y11*Z11 -> 0 | AB11: 12 | AC11: 90000 | AD11: =AB11*AC11 -> 1080000 | AE11: 2 | AF11: 30000 | AG11: =AE11*AF11 -> 60000 | AH11: 1 | AI11: 60000 | AJ11: =AH11*AI11 -> 60000
E12: =SUM(E6:E11) -> 39 | F12: =SUM(F6:F11) -> 130 | I12: =SUM(I6:I11) -> 130
B13: TABLET | H13: TABLET
B14: DIVISION | C14: 3 YEARS & BELOW | D14: ABOVE 3 YEARS | E14: FOR RELACEMENT | F14: TOTAL | H14: DIVISION | I14: INVENTORY
B15: EPRED | C15: 20 | F15: =C15+D15 -> 20 | H15: EPRED | I15: 20
B16: EPSMD | C16: =COUNTIF(Tablet!F28:F36,"<>") -> 9 | F16: =C16+D16 -> 9 | H16: EPSMD | I16: 11
B17: EPMPD | C17: =COUNTIF(Tablet!F28:F36,"<>") -> 9 | F17: =C17+D17 -> 9 | H17: EPMPD | I17: 11
B18: AFETD | C18: 12 | F18: =C18+D18 -> 12 | H18: AFETD | I18: 12
B19: EVIMD | C19: 12 | F19: =C19+D19 -> 12 | H19: EVIMD | I19: 12
B20: NED | C20: =COUNTIF(Tablet!F50:F58,"<>") -> 8 | F20: =C20+D20 -> 8 | H20: NED | I20: 8
E21: =SUM(E15:E20) -> 0 | F21: =SUM(F15:F20) -> 70 | I21: =SUM(I15:I20) -> 74
B22: PRINTER | H22: PRINTER
B23: DIVISION | C23: 3 YEARS & BELOW | D23: ABOVE 3 YEARS | E23: FOR RELACEMENT | F23: TOTAL | H23: DIVISION | I23: INVENTORY
B24: EPRED | D24: 3 | E24: 3 | F24: =C24+D24 -> 3 | H24: EPRED | I24: 3
B25: EPSMD | D25: 5 | E25: 5 | F25: =C25+D25 -> 5 | H25: EPSMD | I25: 5
B26: EPMPD | C26: 1 | F26: =C26+D26 -> 1 | H26: EPMPD | I26: 1
B27: AFETD | D27: 2 | E27: 2 | F27: =C27+D27 -> 2 | H27: AFETD | I27: 2
B28: EVIMD | C28: 2 | F28: =C28+D28 -> 2 | H28: EVIMD | I28: 2
B29: NED | C29: 1 | D29: 1 | E29: 1 | F29: =C29+D29 -> 2 | H29: NED | I29: 2
E30: =SUM(E24:E29) -> 11 | F30: =SUM(F24:F29) -> 15 | I30: =SUM(I28:I29) -> 4

Sheet Data
A1: No. | B1: Full Name | C1: Initials | D1: Division | E1: Position | F1: Plantilla
A2: 1 | B2: Editha T. Ramos | C2: ETR | D2: EPRED | E2: Chief Science Research Specialist | F2: Regular
A3: 2 | B3: Roselle L. Ibuna | C3: RLI | D3: EPRED | E3: OIC-Supervising Science Research Specialist | F3: Regular
A4: 3 | B4: Joan C. Escalona | C4: JCE | D4: EPRED | E4: Supervising Science Research Specialist | F4: Regular
A5: 4 | B5: Steven Ivan G. Caiña | C5: SIGC | D5: EPRED | E5: OIC-Supervising Science Research Specialist | F5: Regular
A6: 5 | B6: Aaron R. Premacio | C6: ARP | D6: EPRED | E6: Senior Science Research Specialist | F6: Regular
A7: 6 | B7: Celedonio Tiu Salle | C7: CTS | D7: EPRED | E7: Senior Science Research Specialist | F7: Regular
A8: 7 | B8: Erwin-Lou D. Peregrino | C8: EDP | D8: EPRED | E8: Senior Science Research Specialist | F8: Regular
A9: 8 | B9: Catherine C. Cadiz | C9: CCC | D9: EPRED | E9: Science Research Specialist II | F9: Regular
A10: 9 | B10: Chesca Mie A. Gaduyon | C10: CMAG | D10: EPRED | E10: Science Research Specialist II | F10: Regular
A11: 10 | B11: Marienelle S. Santos | C11: MSS | D11: EPRED | E11: Science Research Specialist II | F11: Regular
A12: 11 | B12: Daniel Vincent P. De Guzman | C12: DVDG | D12: EPRED | E12: Science Research Specialist II | F12: Regular
A13: 12 | B13: Von Jari A. Anievas | C13: VJA | D13: EPRED | E13: Science Research Specialist I | F13: Regular
... A53: 51 | B53: Jewel R. Balon | C53: JRB | D53: NED | E53: Science Research Specialist I | F53: Regular
A54: 52 | B54: Andresito F. Ulgado | C54: AFU | D54: EVIMD | E54: OIC Chief
A55: 53 | B55: Andre Luis D. Reyes | C55: ALDR | D55: EVIMD | E55: Supervising Science Research Specialist
A56: 54 | B56: Dwane Darcy D. Cayonte | C56: DDDC | D56: EVIMD | E56: Supervising Science Research Specialist
A57: 55 | B57: Peter A. Sablay | C57: PAS | D57: EVIMD | E57: Senior Science Research Specialist
A58: 56 | B58: Oliver L. Desamito | C58: OLD | D58: EVIMD | E58: Senior Science Research Specialist
A59: 57 | B59: Dante L. Castillo | C59: DLC | D59: EVIMD | E59: Senior Science Research Specialist
A60: 58 | B60: Jairus Drei E. Geronimo | C60: JDEG | D60: EVIMD | E60: Science Research Specialist II
A61: 59 | B61: Ma. April C. Fornoles | C61: MACF | D61: EVIMD | E61: Science Research Specialist II
A62: 60 | B62: Patrick Carlo C. Andres | C62: PCCA | D62: EVIMD | E62: Science Research Specialist II
A63: 61 | B63: Jenny C. Ramos | C63: JCR | D63: EVIMD | E63: Science Research Specialist I
A64: 62 | B64: Justin Vincent Delarmente | C64: JVD | D64: EVIMD | E64: Science Research Specialist I
A65: 63 | B65: Erika F. Delos Reyes | C65: EFDR | D65: EVIMD | E65: Science Research Specialist I
A66: 64 | B66: Raffy B. Apostol | C66: RBA | D66: EVIMD | E66: Science Research Specialist I
A67: 65 | B67: Lourdes Maria A. Capricho | C67: LMAC | D67: AFETD | E67: Chief | F67: Regular
A68: 66 | B68: Arnel Mathew C. Garcia | C68: AMCG | D68: AFETD | E68: Supervising Science Research Specialist | F68: Regular
A69: 67 | B69: Rosalie Joan D. R. Sotelo | C69: RJRDS | D69: AFETD | E69: Supervising Science Research Specialist | F69: Regular
A70: 68 | B70: Alpres Russel S. Bustillo | C70: ARSB | D70: AFETD | E70: Senior Science Research Specialist | F70: Regular
A71: 69 | B71: Ron Ron D. Madera | C71: RRDM | D71: AFETD | E71: Senior Science Research Specialist | F71: Regular
A72: 70 | B72: Robert Jae G. Legaspi | C72: RJGL | D72: AFETD | E72: Senior Science Research Specialist | F72: Regular
A73: 71 | B73: Ashley F. Rivera | C73: AFR | D73: AFETD | E73: Senior Science Research Specialist | F73: Regular
A74: 72 | B74: Lianne Bea Y. Jaca | C74: LBYJ | D74: AFETD | E74: Senior Science Research Specialist | F74: Regular
A75: 73 | B75: Jorge Vincent R. Bitoon | C75: JVRB | D75: AFETD | E75: Senior Science Research Specialist | F75: Regular
A76: 74 | B76: John Jomari M. Garcia | C76: JJMG | D76: AFETD | E76: Science Research Specialist II | F76: Regular
A77: 75 | B77: Charmaine Pearl L. Aquino | C77: CPLA | D77: AFETD | E77: Science Research Specialist II | F77: Regular
A78: 76 | B78: Winston Rod R. Nicodemus | C78: WRRN | D78: AFETD | E78: Science Research Specialist II | F78: Regular
... A116: 30 | B116: Vic Anthony P. Cariola | C116: VAPC | D116: AFETD | E116: Project Support Staff | F116: Outsourced
...
